2025-09-29 13:02:11,268 - root - INFO - Entered the try block of exception.py
