[2025-09-29 13:04:54,676 - root] - INFO - Entered the try block of exception.py
